2021-12-18 04:51:40,275 INFO    MainThread:77265 [internal.py:wandb_internal():88] W&B internal server running at pid: 77265, started at: 2021-12-18 04:51:40.275365
2021-12-18 04:51:40,277 DEBUG   HandlerThread:77265 [handler.py:handle_request():120] handle_request: check_version
2021-12-18 04:51:40,277 INFO    WriterThread:77265 [datastore.py:open_for_write():77] open: /home/jhmoon/mlp-mixer-pytorch/mlp_mixer_pytorch/wandb/run-20211218_045139-1ii76xrh/run-1ii76xrh.wandb
2021-12-18 04:51:40,278 DEBUG   SenderThread:77265 [sender.py:send():160] send: header
2021-12-18 04:51:40,278 DEBUG   SenderThread:77265 [sender.py:send():160] send: request
2021-12-18 04:51:40,278 DEBUG   SenderThread:77265 [sender.py:send_request():169] send_request: check_version
2021-12-18 04:51:40,316 DEBUG   SenderThread:77265 [sender.py:send():160] send: run
2021-12-18 04:51:40,524 ERROR   SenderThread:77265 [internal_api.py:execute():127] 404 response executing GraphQL.
2021-12-18 04:51:40,525 ERROR   SenderThread:77265 [internal_api.py:execute():128] {"errors":[{"message":"entity mixer not found during upsertBucket","path":["upsertBucket"]}],"data":{"upsertBucket":null}}
2021-12-18 04:51:41,317 INFO    WriterThread:77265 [datastore.py:close():258] close: /home/jhmoon/mlp-mixer-pytorch/mlp_mixer_pytorch/wandb/run-20211218_045139-1ii76xrh/run-1ii76xrh.wandb
2021-12-18 04:51:41,317 INFO    HandlerThread:77265 [handler.py:finish():624] shutting down handler
2021-12-18 04:51:41,317 ERROR   MainThread:77265 [internal.py:wandb_internal():158] Thread SenderThread:
Traceback (most recent call last):
  File "/home/jhmoon/anaconda3/envs/torch_ot/lib/python3.8/site-packages/wandb/old/retry.py", line 96, in __call__
    result = self._call_fn(*args, **kwargs)
  File "/home/jhmoon/anaconda3/envs/torch_ot/lib/python3.8/site-packages/wandb/sdk/internal/internal_api.py", line 130, in execute
    six.reraise(*sys.exc_info())
  File "/home/jhmoon/anaconda3/envs/torch_ot/lib/python3.8/site-packages/six.py", line 703, in reraise
    raise value
  File "/home/jhmoon/anaconda3/envs/torch_ot/lib/python3.8/site-packages/wandb/sdk/internal/internal_api.py", line 124, in execute
    return self.client.execute(*args, **kwargs)
  File "/home/jhmoon/anaconda3/envs/torch_ot/lib/python3.8/site-packages/wandb/vendor/gql-0.2.0/gql/client.py", line 52, in execute
    result = self._get_result(document, *args, **kwargs)
  File "/home/jhmoon/anaconda3/envs/torch_ot/lib/python3.8/site-packages/wandb/vendor/gql-0.2.0/gql/client.py", line 60, in _get_result
    return self.transport.execute(document, *args, **kwargs)
  File "/home/jhmoon/anaconda3/envs/torch_ot/lib/python3.8/site-packages/wandb/vendor/gql-0.2.0/gql/transport/requests.py", line 39, in execute
    request.raise_for_status()
  File "/home/jhmoon/anaconda3/envs/torch_ot/lib/python3.8/site-packages/requests/models.py", line 943, in raise_for_status
    raise HTTPError(http_error_msg, response=self)
requests.exceptions.HTTPError: 404 Client Error: Not Found for url: https://api.wandb.ai/graphql

During handling of the above exception, another exception occurred:

Traceback (most recent call last):
  File "/home/jhmoon/anaconda3/envs/torch_ot/lib/python3.8/site-packages/wandb/apis/normalize.py", line 24, in wrapper
    return func(*args, **kwargs)
  File "/home/jhmoon/anaconda3/envs/torch_ot/lib/python3.8/site-packages/wandb/sdk/internal/internal_api.py", line 886, in upsert_run
    response = self.gql(mutation, variable_values=variable_values, **kwargs)
  File "/home/jhmoon/anaconda3/envs/torch_ot/lib/python3.8/site-packages/wandb/old/retry.py", line 105, in __call__
    if not check_retry_fn(e):
  File "/home/jhmoon/anaconda3/envs/torch_ot/lib/python3.8/site-packages/wandb/util.py", line 713, in no_retry_auth
    raise CommError("Permission denied, ask the project owner to grant you access")
wandb.errors.CommError: Permission denied, ask the project owner to grant you access

During handling of the above exception, another exception occurred:

Traceback (most recent call last):
  File "/home/jhmoon/anaconda3/envs/torch_ot/lib/python3.8/site-packages/wandb/sdk/internal/internal_util.py", line 54, in run
    self._run()
  File "/home/jhmoon/anaconda3/envs/torch_ot/lib/python3.8/site-packages/wandb/sdk/internal/internal_util.py", line 95, in _run
    self._process(record)
  File "/home/jhmoon/anaconda3/envs/torch_ot/lib/python3.8/site-packages/wandb/sdk/internal/internal.py", line 279, in _process
    self._sm.send(record)
  File "/home/jhmoon/anaconda3/envs/torch_ot/lib/python3.8/site-packages/wandb/sdk/internal/sender.py", line 162, in send
    send_handler(record)
  File "/home/jhmoon/anaconda3/envs/torch_ot/lib/python3.8/site-packages/wandb/sdk/internal/sender.py", line 541, in send_run
    self._init_run(run, config_value_dict)
  File "/home/jhmoon/anaconda3/envs/torch_ot/lib/python3.8/site-packages/wandb/sdk/internal/sender.py", line 563, in _init_run
    server_run, inserted = self._api.upsert_run(
  File "/home/jhmoon/anaconda3/envs/torch_ot/lib/python3.8/site-packages/wandb/apis/normalize.py", line 62, in wrapper
    six.reraise(CommError, CommError(message, err), sys.exc_info()[2])
  File "/home/jhmoon/anaconda3/envs/torch_ot/lib/python3.8/site-packages/six.py", line 702, in reraise
    raise value.with_traceback(tb)
  File "/home/jhmoon/anaconda3/envs/torch_ot/lib/python3.8/site-packages/wandb/apis/normalize.py", line 24, in wrapper
    return func(*args, **kwargs)
  File "/home/jhmoon/anaconda3/envs/torch_ot/lib/python3.8/site-packages/wandb/sdk/internal/internal_api.py", line 886, in upsert_run
    response = self.gql(mutation, variable_values=variable_values, **kwargs)
  File "/home/jhmoon/anaconda3/envs/torch_ot/lib/python3.8/site-packages/wandb/old/retry.py", line 105, in __call__
    if not check_retry_fn(e):
  File "/home/jhmoon/anaconda3/envs/torch_ot/lib/python3.8/site-packages/wandb/util.py", line 713, in no_retry_auth
    raise CommError("Permission denied, ask the project owner to grant you access")
wandb.errors.CommError: Permission denied, ask the project owner to grant you access
2021-12-18 04:51:43,333 INFO    MainThread:77265 [internal.py:handle_exit():78] Internal process exited
